{"success":false,"exitStatus":1,"errorMessage":"Traceback (most recent call last):\n  File \"/usr/local/lib/python3.10/runpy.py\", line 196, in _run_module_as_main\n    return _run_code(code, main_globals, None,\n  File \"/usr/local/lib/python3.10/runpy.py\", line 86, in _run_code\n    exec(code, run_globals)\n  File \"/usr/local/lib/python3.10/site-packages/horn_analysis/plotter.py\", line 32, in <module>\n    main() \n  File \"/usr/local/lib/python3.10/site-packages/horn_analysis/plotter.py\", line 29, in main\n    plot_results(args.input, args.output)\n  File \"/usr/local/lib/python3.10/site-packages/horn_analysis/plotter.py\", line 10, in plot_results\n    df = pd.read_csv(input_file)\n  File \"/usr/local/lib/python3.10/site-packages/pandas/io/parsers/readers.py\", line 1026, in read_csv\n    return _read(filepath_or_buffer, kwds)\n  File \"/usr/local/lib/python3.10/site-packages/pandas/io/parsers/readers.py\", line 620, in _read\n    parser = TextFileReader(filepath_or_buffer, **kwds)\n  File \"/usr/local/lib/python3.10/site-packages/pandas/io/parsers/readers.py\", line 1620, in __init__\n    self._engine = self._make_engine(f, self.engine)\n  File \"/usr/local/lib/python3.10/site-packages/pandas/io/parsers/readers.py\", line 1880, in _make_engine\n    self.handles = get_handle(\n  File \"/usr/local/lib/python3.10/site-packages/pandas/io/common.py\", line 873, in get_handle\n    handle = open(\nFileNotFoundError: [Errno 2] No such file or directory: 'final_results.csv'","errorReport":"Error executing process > 'generate_plots'\n\nCaused by:\n  Process `generate_plots` terminated with an error exit status (1)\n\n\nCommand executed:\n\n  python3 -m horn_analysis.plotter         --input final_results.csv         --output frequency_response.png\n\nCommand exit status:\n  1\n\nCommand output:\n  (empty)\n\nCommand error:\n  Traceback (most recent call last):\n    File \"/usr/local/lib/python3.10/runpy.py\", line 196, in _run_module_as_main\n      return _run_code(code, main_globals, None,\n    File \"/usr/local/lib/python3.10/runpy.py\", line 86, in _run_code\n      exec(code, run_globals)\n    File \"/usr/local/lib/python3.10/site-packages/horn_analysis/plotter.py\", line 32, in <module>\n      main() \n    File \"/usr/local/lib/python3.10/site-packages/horn_analysis/plotter.py\", line 29, in main\n      plot_results(args.input, args.output)\n    File \"/usr/local/lib/python3.10/site-packages/horn_analysis/plotter.py\", line 10, in plot_results\n      df = pd.read_csv(input_file)\n    File \"/usr/local/lib/python3.10/site-packages/pandas/io/parsers/readers.py\", line 1026, in read_csv\n      return _read(filepath_or_buffer, kwds)\n    File \"/usr/local/lib/python3.10/site-packages/pandas/io/parsers/readers.py\", line 620, in _read\n      parser = TextFileReader(filepath_or_buffer, **kwds)\n    File \"/usr/local/lib/python3.10/site-packages/pandas/io/parsers/readers.py\", line 1620, in __init__\n      self._engine = self._make_engine(f, self.engine)\n    File \"/usr/local/lib/python3.10/site-packages/pandas/io/parsers/readers.py\", line 1880, in _make_engine\n      self.handles = get_handle(\n    File \"/usr/local/lib/python3.10/site-packages/pandas/io/common.py\", line 873, in get_handle\n      handle = open(\n  FileNotFoundError: [Errno 2] No such file or directory: 'final_results.csv'\n\nWork dir:\n  /Users/timrichardson/projects/horn/.nf-test/tests/6615a250f7b3e6847de644d94a117973/work/80/71c04c64a568b4c8def89b2ef33748\n\nContainer:\n  horn-analysis:latest\n\nTip: when you have fixed the problem you can continue the execution adding the option `-resume` to the run command line"}